Workbook

Sheet 00_INDEX
A1: LAGNA MASTER · Vedic Jyotish Chart Analysis Engine · v5
A2: Demo chart: India Independence Day · 15 Aug 1947 · Taurus Lagna · Mars MD 2025-2032 · Swiss Ephemeris live (+-0.001 deg) · v5: corruption fixed, D60 5star, Shadbala 5star, VBA macro, batch_charts.py
A3: ✓ | B3: Sheet | C3: Purpose | D3: Feeds into | E3: Rating | F3: Known gap / status
A4: INPUT · Birth data entry · Only section requiring any input
A5: ✓ | B5: INPUT_BirthData | C5: Date, time, place → JDN, Lahiri ayanamsha (23.125451°), Dasha seed | D5: → CALC_PlanetLongitudes, CALC_DashaActive | E5: ★★★★★ | F5: Fully automated after initial data entry. No Python script needed for natal chart.
B6: ↳ CALC_PlanetLongitudes (auto) | C6: Reads Swiss Ephemeris absolute longitudes directly. Derives sign + degree. No ephemeris formulae fallback for live data.
B7: ↳ INPUT_Chart (auto) | C7: Sign + degree auto-populated from CALC_PlanetLongitudes. No manual entry needed.
B8: ↳ INPUT_Gochar (manual / API) | C8: Transit positions. Update manually or via ephemeris_api.py --gochar
B9: ↳ INPUT_Chart_Scenario (optional) | C9: What-if chart. Mirrors INPUT_Chart by default; override manually for counterfactual analysis.
A10: CALC · Computation engine · 38 sheets · No user edits required
A11: ✓ | B11: CALC_SwissEphemeris_Live | C11: Swiss Ephemeris positions + daily speeds. Written by ephemeris_api.py. | D11: → CALC_PlanetLongitudes, CALC_Shadbala | E11: ★★★★★ | F11: ±0.001° all planets. Chesta Bala speeds live. Refresh by running ephemeris_api.py.
A12: ✓ | B12: CALC_PlanetLongitudes | C12: Absolute sidereal longitudes from Swiss Ephemeris. Sign/degree derived. | D12: → INPUT_Chart (auto-fill), CALC_PlanetPositions | E12: ★★★★★ | F12: Reads CALC_SwissEphemeris_Live col B directly. ephemeris formulae formulae in col B dormant (reference only).
A13: ✓ | B13: CALC_PlanetPositions | C13: Central engine: sign, deg, nakshatra, pada, dignity, retrograde, aspects. | D13: → All 75 SCORE_H* sheets | E13: ★★★★★ | F13: 10 bodies live. Lagna nakshatra = N/A by design.
A14: ✓ | B14: CALC_BhaveshMap | C14: 12 house lords + Kendra/Trikona/Dukshthan classification. | D14: → SCORE_H* R04-R08 | E14: ★★★★★ | F14: —
A15: ✓ | B15: CALC_Ashtakavarga | C15: 8-source bindu grid × 7 planets. SAV = [44,19,27,27,30,25,23,28,20,29,35,30]. | D15: → SCORE_H* R23 | E15: ★★★★★ | F15: Verified against two independent reference sources. Lagna double-count + Venus/Mars rule fixed.
A16: ✓ | B16: CALC_Shadbala | C16: 16-component Shadbala. Chesta from Swiss Ephemeris daily speeds. | D16: → OUTPUT_StrengthDashboard | E16: ★★★★★ | F16: 16 components live. Chesta from pyswisseph speed. Ayana: BPHS 0-60 (correct). Drik: sign-aspects.
A17: ✓ | B17: CALC_DashaActive | C17: Vimshottari chain from Moon nakshatra. Mars MD 09-Sep-2025 → 08-Sep-2032. | D17: → SCORE_AllHouses col M, OUTPUT_DashaTimeline | E17: ★★★★★ | F17: Full 9-period chain live. Dasha start planet from REF_Nakshatra (B31 helper).
A18: ✓ | B18: CALC_NarayanaDasa | C18: Sign-based Narayana Dasha with PVRNR directional reversal. | D18: → OUTPUT_DashaTimeline | E18: ★★★★★ | F18: PVRNR reversal implemented for even-sign Lagnas.
A19: ✓ | B19: CALC_DivisionalMap | C19: D1–D60 varga signs for all 10 bodies. | D19: → CALC_VimshopakaBala, CALC_Shadbala | E19: ★★★★★ | F19: —
A20: ✓ | B20: CALC_RuleInteractionEngine | C20: 22 cross-rule interaction pairs × 12 houses. | D20: → SCORE_AllHouses col V | E20: ★★★★★ | F20: Live. Was stub (all zeros) in v3. 8 of 30 REF pairs not yet wired (nullified/contextual — minor).
A21: ✓ | B21: CALC_Argala | C21: Net Argala per house (H2/H4/H11 benefic/malefic positions). | D21: → SCORE_AllHouses col P | E21: ★★★★★ | F21: —
A22: ✓ | B22: CALC_KPSubLord | C22: KP sub-lord for all 10 bodies. | D22: → SCORE_AllHouses col T | E22: ★★★★★ | F22: Dormant in Parashari mode. Switch REF_Config B6 → KP to activate.
... A25: ~ | B25: CALC_D60_Shastiamsha | C25: D60 sign + division name. | D25: → OUTPUT_StrengthDashboard | E25: ★★★★★ | F25: E24=SwissEph satisfied. +-0.001 deg all planets. All 60 D60 divisions reliable.
A26: REF · Read-only lookup tables · 28 sheets · BPHS-sourced constants
A27: ✓ | B27: REF_Config | C27: School (Parashari/KP/Jaimini), ayanamsha, node type, retrograde toggles. All wired. | D27: → All CALC_ sheets | E27: ★★★★★ | F27: —
A28: ✓ | B28: REF_ShadbalaData | C28: Exalt degrees (sidereal), Kendradi weights, Vara/Masa/Abda lords, Drik weights. | D28: → CALC_Shadbala | E28: ★★★★★ | F28: Added v4.
A29: ✓ | B29: REF_Nakshatra | C29: 27 nakshatras × 42 attributes. Col L = Dasha lord, col M = years. | D29: → CALC_DashaActive, INPUT_BirthData B31 | E29: ★★★★★ | F29: —
A30: ✓ | B30: REF_Zodiac, REF_Planets, REF_Dignity, REF_Aspects | C30: Sign attributes, planet attributes, dignity table, aspect matrix. | D30: → CALC_PlanetPositions | E30: ★★★★★ | F30: —
A31: ✓ | B31: REF_RuleInteractionMatrix | C31: 30 rule-pair definitions with modifiers. 22 implemented in CALC_RIE. | D31: → CALC_RuleInteractionEngine | E31: ★★★★★ | F31: 8 nullified/contextual pairs pending.
A32: ✓ | B32: REF_KPSubLordTable | C32: 9 sub-lord sizes + 27 nakshatra start degrees. | D32: → CALC_KPSubLord | E32: ★★★★★ | F32: —
A33: ✓ | B33: REF_NarayanaDasaRules | C33: Sign durations + PVRNR directional rules. | D33: → CALC_NarayanaDasa | E33: ★★★★★ | F33: —
A34: ✓ | B34: REF_EmpiricaSchema | C34: Empirical event log schema for accuracy calibration. | D34: → OUTPUT_ValidationDashboard | E34: ★★☆☆☆ | F34: Framework only. Requires 50+ real events.
A35: SCORE · 23-rule house scoring · 75 sheets · 6 Lagna axes
A36: ✓ | B36: SCORE_AllHouses | C36: Composite: base (J) + Argala (P) + GrahaYuddha (Q) + KP (T) + RasiDrishti (U) + RuleInteraction (V) = col S. All OUTPUT sheets read col S. | D36: → All OUTPUT sheets | E36: ★★★★★ | F36: Col S = authoritative final score. S17 = average across 12 houses.
A37: ✓ | B37: SCORE_H1_Self … SCORE_H12_Liberation (D1) | C37: 23 rules × 12 houses from D1 Lagna. | D37: → SCORE_AllHouses col J | E37: ★★★★★ | F37: All 12 live.
A38: ✓ | B38: SCORE_H1_Chandra … H12_Chandra | C38: 23 rules from Moon as Lagna. | D38: → OUTPUT_MultiLagna | E38: ★★★★★ | F38: —
A39: ✓ | B39: SCORE_H1_Surya … H12_Surya | C39: 23 rules from Sun as Lagna. | D39: → OUTPUT_MultiLagna | E39: ★★★★★ | F39: —
A40: ✓ | B40: SCORE_H1_D9 … H12_D9 | C40: 23 rules from D9 Navamsha Lagna. | D40: → CALC_CompositeVargaScore | E40: ★★★★★ | F40: —
A41: ✓ | B41: SCORE_H1_D10 … H12_D10 | C41: 23 rules from D10 Dasamsha Lagna. | D41: → CALC_CompositeVargaScore | E41: ★★★★★ | F41: —
A42: ✓ | B42: SCORE_Karakamsha + H1–H11 | C42: 13 sheets from Karakamsha Lagna. | D42: → OUTPUT_LifePressureIndex_Full | E42: ★★★★★ | F42: H3 and H8 score = −0.5 (computed, correct).
...

Sheet INPUT_BirthData
A1: INPUT_BirthData — Manual Entry + Formula Sheet | L1: =HYPERLINK("#'00_INDEX'!A1","<- Index") -> <- Index
A2: Blue cells = enter manually. Black cells = auto-calculated. Do NOT edit black cells — they contain formulas.
A4: Section A — Core birth data (enter these 5 cells)
A5: Date of birth | B5: 17394 | C5: ← Enter | D5: Format: enter as DD/MM/YYYY. Cell format → Date
A6: Time of birth (local) | B6: 0 | C6: ← Enter | D6: Enter as HH:MM e.g. 08:30 — Cell format → Time (HH:MM)
A7: City of birth | B7: New Delhi | C7: ← Enter | D7: e.g. Mumbai, Delhi, Chennai
A8: Country of birth | B8: India | C8: ← Enter | D8: e.g. India
A9: UTC offset (hours) | B9: 5.5 | C9: ← Enter | D9: +5.5 = IST. Pre-1947 Mumbai = +4.85, Calcutta = +5.88, Madras = +5.35
A10: Ayanamsha system | B10: Lahiri | C10: ← Enter | D10: Lahiri = recommended for Vedic. Raman = alternative. KP = Krishnamurti
A11: Time confidence | B11: Exact | C11: ← Enter | D11: Exact / ±15min / ±1hr / Unknown — affects reliability of Lagna
A13: Section B — Location coordinates (look up from Google Maps or geocoder)
A14: Latitude | B14: 28.6139 | C14: ← Enter | D14: Degrees North. Mumbai = 18.9750. Delhi = 28.6139. Chennai = 13.0827
A15: Longitude | B15: 77.209 | C15: ← Enter | D15: Degrees East. Mumbai = 72.8258. Delhi = 77.2090. Chennai = 80.2707
A17: Section C — Auto-calculated from Sections A + B
A18: UTC birth date-time | B18: =IFERROR(IF(B5="← Enter","← Enter date first",TEXT(B5+IF(B6="← Enter",0,TIMEVALUE(TEXT(B6,"HH:MM")))-B9/24,"DD-MMM-YYYY HH:MM")),"Check date format") -> 14-Aug-1947 18:30 | C18: AUTO | D18: Date + local time − UTC offset. This is what ephemeris tools use.
A19: Julian Day Number (JDN) | B19: =IFERROR(IF(B5="← Enter","← Enter date",INT(365.25*(IF(MONTH(B5)<=2,YEAR(B5)-1,YEAR(B5))+4716))+INT(30.6001*(IF(MONTH(B5)<=2,MONTH(B5)+13,MONTH(B5)+1)))+DAY(B5)-1524.5),"—") -> 2432425.5 | C19: AUTO | D19: Continuous count from 1 Jan 4713 BC noon. Input format for Swiss Ephemeris.
A20: Ayanamsha value at birth | B20: 23.125451 | C20: AUTO | D20: Linear approx — accurate to ±0.05°. Use API for exact value.
A21: Chart Confidence | B21: =IFERROR(IF(AND(B11="Exact",COUNTIF(CALC_PlanetLongitudes!$H$7:$H$16,"<>")=0),"GREEN - High confidence",IF(OR(B11="Unknown",COUNTIF(CALC_PlanetLongitudes!$H$7:$H$16,"<>")>=3),"RED - Low confidence","AMBER - Verify boundary planets")),"—") -> RED - Low confidence | C21: =IFERROR(IF(E24="API","← API (ephemeris API ±0.0001°)","← Manual entry"),"← Manual entry") -> ← Manual entry | D21: GREEN = Exact time + no boundary planets. AMBER = minor uncertainty. RED = Unknown time or 3+ boundary planets.
A22: 🔄 Refresh chart | B22: Run: python3 swiss_eph_engine.py -- same folder, Terminal. See NOTES_VBAMacro for VBA button. | C22: Terminal / VBA macro | D22: Replaces localhost:5050. Swiss Ephemeris writes +-0.001 deg directly. VBA: Alt+F11 -> paste Sub from NOTES_VBAMacro -> assign to B22.
A23: Server: python3 ephemeris API_lagna_v3.py --server │ One-shot: python3 ephemeris API_lagna_v3.py --gochar │ Credentials: python3 ephemeris API_lagna_v3.py --save-credentials
A24: Moon total longitude (0°–360°) | B24: =IFERROR((MATCH(INPUT_Chart!$C$7,{"Aries","Taurus","Gemini","Cancer","Leo","Virgo","Libra","Scorpio","Sagittarius","Capricorn","Aquarius","Pisces"},0)-1)*30+INPUT_Chart!$D$7,0) -> 93.9835 | C24: AUTO from INPUT_Chart | D24: Enter from your chart tool. e.g. Moon at 15° Taurus = 30+15 = 45.0000° | E24: SwissEph
A25: Moon Nakshatra | B25: =IFERROR(INDEX(REF_Nakshatra!$B$6:$B$32,MATCH((MATCH(INPUT_Chart!$C$7,{"Aries","Taurus","Gemini","Cancer","Leo","Virgo","Libra","Scorpio","Sagittarius","Capricorn","Aquarius","Pisces"},0)-1)*30+INPUT_Chart!$D$7,REF_Nakshatra!$H$6:$H$32,1)),"Enter Moon sign+degree in INPUT_Chart") -> Pushya | C25: AUTO | D25: Derived from Moon longitude. Each Nakshatra = 13°20' = 13.3333° | E25: 17-Mar-2026 19:18:26
A26: Moon Nakshatra Pada | B26: =IFERROR(MIN(4,INT(((MATCH(INPUT_Chart!$C$7,{"Aries","Taurus","Gemini","Cancer","Leo","Virgo","Libra","Scorpio","Sagittarius","Capricorn","Aquarius","Pisces"},0)-1)*30+INPUT_Chart!$D$7-INDEX(REF_Nakshatra!$H$6:$H$32,MATCH((MATCH(INPUT_Chart!$C$7,{"Aries","Taurus","Gemini","Cancer","Leo","Virgo","Libra","Scorpio","Sagittarius","Capricorn","Aquarius","Pisces"},0)-1)*30+INPUT_Chart!$D$7,REF_Nakshatra!$H$6:$H$32,1)))/(40/12))+1),"Enter Moon sign+degree in INPUT_Chart") -> 1 | C26: AUTO | D26: Pada 1–4 within the Nakshatra (each = 3°20'). Maps to Navamsha sign.
A27: Sunrise UTC (for Tribhaga) | B27: =IFERROR(_xludf.let(moon_lon,B24,nak_pos,MOD(moon_lon,(40/3)),pada_pos,MOD(nak_pos,(40/12)),IF(OR(pada_pos<0.5,(40/12)-pada_pos<0.5),"⚠ VERIFY: Moon within 0.5° of pada boundary (ephemeris formulae ±0.3° risk)","✓ Moon pada clear of boundary")),"Enter Moon position") -> Enter Moon position | C27: Written by ephemeris API_lagna_v4.py | D27: Written by ephemeris API_lagna_v4.py via panchang API. Used by CALC_Shadbala Tribhaga Bala (col H) to replace HOUR() approximation. RESOLVES Issue #14 when v4 script has been run.
A28: Nakshatra fraction remaining | B28: =IFERROR(ROUND(1-((MATCH(INPUT_Chart!$C$7,{"Aries","Taurus","Gemini","Cancer","Leo","Virgo","Libra","Scorpio","Sagittarius","Capricorn","Aquarius","Pisces"},0)-1)*30+INPUT_Chart!$D$7-INDEX(REF_Nakshatra!$H$6:$H$32,MATCH((MATCH(INPUT_Chart!$C$7,{"Aries","Taurus","Gemini","Cancer","Leo","Virgo","Libra","Scorpio","Sagittarius","Capricorn","Aquarius","Pisces"},0)-1)*30+INPUT_Chart!$D$7,REF_Nakshatra!$H$6:$H$32,1)))/(40/3),4),"—") -> 0.9512 | D28: e.g. 0.5000 = Moon is halfway through its Nakshatra at birth → 50% of first Dasha remains
A29: Starting Dasha duration (years) | B29: =IFERROR(INDEX(REF_Nakshatra!$M$6:$M$32,MATCH((MATCH(INPUT_Chart!$C$7,{"Aries","Taurus","Gemini","Cancer","Leo","Virgo","Libra","Scorpio","Sagittarius","Capricorn","Aquarius","Pisces"},0)-1)*30+INPUT_Chart!$D$7,REF_Nakshatra!$H$6:$H$32,1)),"—") -> 19 | D29: Total years in the starting Mahadasha (e.g. Moon = 10, Venus = 20)
A30: Years remaining at birth | B30: =IFERROR(ROUND(B28*B29,2),"—") -> 18.07 | D30: How many years of the first Dasha are left from birth date forward
A31: Dasha starting planet | B31: =IFERROR(INDEX(REF_Nakshatra!$L$6:$L$32,MATCH($B$25,REF_Nakshatra!$B$6:$B$32,0)),"—") -> Saturn | C31: AUTO from B25 | D31: Nakshatra lord → Vimshottari Dasha start planet
A32: Section E — Vimshottari Dasha timeline (from birth date)
A33: Mahadasha planet | B33: Start date | C33: End date | D33: Years
A34: =IFERROR(INDEX({"Ketu","Venus","Sun","Moon","Mars","Rahu","Jupiter","Saturn","Mercury"},MOD(MATCH(B$31,{"Ketu","Venus","Sun","Moon","Mars","Rahu","Jupiter","Saturn","Mercury"},0)-1+0,9)+1),"—") -> Saturn | B34: =IFERROR(IF(ISNUMBER(B5),B5,DATEVALUE(TEXT(B5,"DD/MM/YYYY"))),"—") -> 17394 | C34: =IFERROR(B34+D34*365.25,"—") -> 23994.068 | D34: =IFERROR(B30,"—") -> 18.07
A35: =IFERROR(INDEX({"Ketu","Venus","Sun","Moon","Mars","Rahu","Jupiter","Saturn","Mercury"},MOD(MATCH(B$31,{"Ketu","Venus","Sun","Moon","Mars","Rahu","Jupiter","Saturn","Mercury"},0)-1+1,9)+1),"—") -> Mercury | B35: =IFERROR(C34,"—") -> 23994.068 | C35: =IFERROR(B35+D35*365.25,"—") -> 30203.318 | D35: =IFERROR(INDEX({7,20,6,10,7,18,16,19,17},MATCH(A35,{"Ketu","Venus","Sun","Moon","Mars","Rahu","Jupiter","Saturn","Mercury"},0)),"—") -> 17
A36: =IFERROR(INDEX({"Ketu","Venus","Sun","Moon","Mars","Rahu","Jupiter","Saturn","Mercury"},MOD(MATCH(B$31,{"Ketu","Venus","Sun","Moon","Mars","Rahu","Jupiter","Saturn","Mercury"},0)-1+2,9)+1),"—") -> Ketu | B36: =IFERROR(C35,"—") -> 30203.318 | C36: =IFERROR(B36+D36*365.25,"—") -> 32760.068 | D36: =IFERROR(INDEX({7,20,6,10,7,18,16,19,17},MATCH(A36,{"Ketu","Venus","Sun","Moon","Mars","Rahu","Jupiter","Saturn","Mercury"},0)),"—") -> 7
A37: =IFERROR(INDEX({"Ketu","Venus","Sun","Moon","Mars","Rahu","Jupiter","Saturn","Mercury"},MOD(MATCH(B$31,{"Ketu","Venus","Sun","Moon","Mars","Rahu","Jupiter","Saturn","Mercury"},0)-1+3,9)+1),"—") -> Venus | B37: =IFERROR(C36,"—") -> 32760.068 | C37: =IFERROR(B37+D37*365.25,"—") -> 40065.068 | D37: =IFERROR(INDEX({7,20,6,10,7,18,16,19,17},MATCH(A37,{"Ketu","Venus","Sun","Moon","Mars","Rahu","Jupiter","Saturn","Mercury"},0)),"—") -> 20
A38: =IFERROR(INDEX({"Ketu","Venus","Sun","Moon","Mars","Rahu","Jupiter","Saturn","Mercury"},MOD(MATCH(B$31,{"Ketu","Venus","Sun","Moon","Mars","Rahu","Jupiter","Saturn","Mercury"},0)-1+4,9)+1),"—") -> Sun | B38: =IFERROR(C37,"—") -> 40065.068 | C38: =IFERROR(B38+D38*365.25,"—") -> 42256.568 | D38: =IFERROR(INDEX({7,20,6,10,7,18,16,19,17},MATCH(A38,{"Ketu","Venus","Sun","Moon","Mars","Rahu","Jupiter","Saturn","Mercury"},0)),"—") -> 6
A39: =IFERROR(INDEX({"Ketu","Venus","Sun","Moon","Mars","Rahu","Jupiter","Saturn","Mercury"},MOD(MATCH(B$31,{"Ketu","Venus","Sun","Moon","Mars","Rahu","Jupiter","Saturn","Mercury"},0)-1+5,9)+1),"—") -> Moon | B39: =IFERROR(C38,"—") -> 42256.568 | C39: =IFERROR(B39+D39*365.25,"—") -> 45909.068 | D39: =IFERROR(INDEX({7,20,6,10,7,18,16,19,17},MATCH(A39,{"Ketu","Venus","Sun","Moon","Mars","Rahu","Jupiter","Saturn","Mercury"},0)),"—") -> 10
A40: =IFERROR(INDEX({"Ketu","Venus","Sun","Moon","Mars","Rahu","Jupiter","Saturn","Mercury"},MOD(MATCH(B$31,{"Ketu","Venus","Sun","Moon","Mars","Rahu","Jupiter","Saturn","Mercury"},0)-1+6,9)+1),"—") -> Mars | B40: =IFERROR(C39,"—") -> 45909.068 | C40: =IFERROR(B40+D40*365.25,"—") -> 48465.818 | D40: =IFERROR(INDEX({7,20,6,10,7,18,16,19,17},MATCH(A40,{"Ketu","Venus","Sun","Moon","Mars","Rahu","Jupiter","Saturn","Mercury"},0)),"—") -> 7
A41: =IFERROR(INDEX({"Ketu","Venus","Sun","Moon","Mars","Rahu","Jupiter","Saturn","Mercury"},MOD(MATCH(B$31,{"Ketu","Venus","Sun","Moon","Mars","Rahu","Jupiter","Saturn","Mercury"},0)-1+7,9)+1),"—") -> Rahu | B41: =IFERROR(C40,"—") -> 48465.818 | C41: =IFERROR(B41+D41*365.25,"—") -> 55040.318 | D41: =IFERROR(INDEX({7,20,6,10,7,18,16,19,17},MATCH(A41,{"Ketu","Venus","Sun","Moon","Mars","Rahu","Jupiter","Saturn","Mercury"},0)),"—") -> 18
A42: =IFERROR(INDEX({"Ketu","Venus","Sun","Moon","Mars","Rahu","Jupiter","Saturn","Mercury"},MOD(MATCH(B$31,{"Ketu","Venus","Sun","Moon","Mars","Rahu","Jupiter","Saturn","Mercury"},0)-1+8,9)+1),"—") -> Jupiter | B42: =IFERROR(C41,"—") -> 55040.318 | C42: =IFERROR(B42+D42*365.25,"—") -> 60884.318 | D42: =IFERROR(INDEX({7,20,6,10,7,18,16,19,17},MATCH(A42,{"Ketu","Venus","Sun","Moon","Mars","Rahu","Jupiter","Saturn","Mercury"},0)),"—") -> 16
A47: Section F — Computed Planet Positions (from CALC_PlanetLongitudes)
...

Sheet INPUT_Chart
A1: INPUT_Chart · Planet Positions · AUTO from CALC_PlanetLongitudes | L1: =HYPERLINK("#'00_INDEX'!A1","<- Index") -> <- Index
A2: ⬇ Enter birth data in INPUT_BirthData — planet positions auto-fill here. ✎ You can override any Sign or Degree cell manually — type directly into col C or D and your value takes precedence. Blue cells = designed for manual entry.
A3: =IFERROR(IF(COUNTIF(CALC_PlanetLongitudes!$H$7:$H$16,"<>")>0,"BOUNDARY ALERT: "&COUNTIF(CALC_PlanetLongitudes!$H$7:$H$16,"<>")&" planet(s) near sign boundary - verify with third-party software",""),"") -> BOUNDARY ALERT: 10 planet(s) near sign boundary - verify with third-party software
A4: Planet / Point | B4: Valid Signs | C4: Sign Placed | D4: Degree (0-29) | E4: Sanskrit Name | F4: Notes
A5: Lagna (Ascendant) | B5: Aries,Taurus,Gemini,Cancer,Leo,Virgo,Libra,Scorpio,Sagittarius,Capricorn,Aquarius,Pisces | C5: =IFERROR(CALC_PlanetLongitudes!$E$7,"—") -> Taurus | D5: =IFERROR(CALC_PlanetLongitudes!$F$7,"—") -> 7.7286 | E5: Mesh | F5: Rising sign — most important input
A6: Sun / Surya | B6: Aries,Taurus,Gemini,Cancer,Leo,Virgo,Libra,Scorpio,Sagittarius,Capricorn,Aquarius,Pisces | C6: =IFERROR(CALC_PlanetLongitudes!$E$8,"—") -> Cancer | D6: =IFERROR(CALC_PlanetLongitudes!$F$8,"—") -> 27.989 | E6: Surya | F6: Soul, father, authority
A7: Moon / Chandramaa | B7: Aries,Taurus,Gemini,Cancer,Leo,Virgo,Libra,Scorpio,Sagittarius,Capricorn,Aquarius,Pisces | C7: =IFERROR(CALC_PlanetLongitudes!$E$9,"—") -> Cancer | D7: =IFERROR(CALC_PlanetLongitudes!$F$9,"—") -> 3.9835 | E7: Chandramaa | F7: Mind, mother, emotions
A8: Mars / Mangal | B8: Aries,Taurus,Gemini,Cancer,Leo,Virgo,Libra,Scorpio,Sagittarius,Capricorn,Aquarius,Pisces | C8: =IFERROR(CALC_PlanetLongitudes!$E$10,"—") -> Gemini | D8: =IFERROR(CALC_PlanetLongitudes!$F$10,"—") -> 7.4562 | E8: Mangal | F8: Energy, siblings, courage
A9: Mercury / Budh | B9: Aries,Taurus,Gemini,Cancer,Leo,Virgo,Libra,Scorpio,Sagittarius,Capricorn,Aquarius,Pisces | C9: =IFERROR(CALC_PlanetLongitudes!$E$11,"—") -> Cancer | D9: =IFERROR(CALC_PlanetLongitudes!$F$11,"—") -> 13.6743 | E9: Budh | F9: Intellect, communication
A10: Jupiter / Brihaspati | B10: Aries,Taurus,Gemini,Cancer,Leo,Virgo,Libra,Scorpio,Sagittarius,Capricorn,Aquarius,Pisces | C10: =IFERROR(CALC_PlanetLongitudes!$E$12,"—") -> Libra | D10: =IFERROR(CALC_PlanetLongitudes!$F$12,"—") -> 25.8777 | E10: Brihaspati | F10: Wisdom, children, fortune
A11: Venus / Shukra | B11: Aries,Taurus,Gemini,Cancer,Leo,Virgo,Libra,Scorpio,Sagittarius,Capricorn,Aquarius,Pisces | C11: =IFERROR(CALC_PlanetLongitudes!$E$13,"—") -> Cancer | D11: =IFERROR(CALC_PlanetLongitudes!$F$13,"—") -> 22.5612 | E11: Shukra | F11: Love, luxury, relationships
A12: Saturn / Shani | B12: Aries,Taurus,Gemini,Cancer,Leo,Virgo,Libra,Scorpio,Sagittarius,Capricorn,Aquarius,Pisces | C12: =IFERROR(CALC_PlanetLongitudes!$E$14,"—") -> Cancer | D12: =IFERROR(CALC_PlanetLongitudes!$F$14,"—") -> 20.473 | E12: Shani | F12: Discipline, karma, longevity
A13: Rahu (N. Node) | B13: Aries,Taurus,Gemini,Cancer,Leo,Virgo,Libra,Scorpio,Sagittarius,Capricorn,Aquarius,Pisces | C13: =IFERROR(CALC_PlanetLongitudes!$E$15,"—") -> Taurus | D13: =IFERROR(CALC_PlanetLongitudes!$F$15,"—") -> 5.0697 | E13: Rahu | F13: Obsession, amplifier — no own sign
A14: Ketu (S. Node) | B14: Aries,Taurus,Gemini,Cancer,Leo,Virgo,Libra,Scorpio,Sagittarius,Capricorn,Aquarius,Pisces | C14: =IFERROR(CALC_PlanetLongitudes!$E$16,"—") -> Scorpio | D14: =IFERROR(CALC_PlanetLongitudes!$F$16,"—") -> 5.0697 | E14: Ketu | F14: Detachment — always 7 signs from Rahu
A16: Moon longitude (for Dasha) | B16: Auto-reads sign+degree from row 7 above | C16: =IFERROR("≈ "&TEXT((MATCH(C7,{"Aries","Taurus","Gemini","Cancer","Leo","Virgo","Libra","Scorpio","Sagittarius","Capricorn","Aquarius","Pisces"},0)-1)*30+D7,"0.00")&"° abs","Enter Moon sign+degree above") -> ≈ 93.98° abs | D16: Used in INPUT_BirthData Dasha calc | E16: Chandramaa | F16: Auto-computed from Moon row — no extra entry needed
A17: REFERENCE: Shubh (Benefic) and Ashubh (Malefic) planets change based on Lagna — see REF_ShubhAshubh sheet

Sheet INPUT_Gochar
A1: INPUT_Gochar · Today's Transit Positions · Enter for Gochar overlay | L1: =HYPERLINK("#'00_INDEX'!A1","<- Index") -> <- Index
A2: Enter today's sidereal (Lahiri) planet positions for transit analysis. Source: reference software > Today's Panchang, ephemeris API, or ephemeris API API. Signs must match INPUT_Chart sign names exactly.
A3: Planet | B3: Transit Sign | C3: Degree | D3: Notes — transit speed
A4: Sun | B4: Pisces | C4: 2.4176 | D4: ~30 days per sign
A5: Moon | B5: Aquarius | C5: 9.365 | D5: ~2.25 days per sign — fastest
A6: Mars | B6: Aquarius | C6: 17.3107 | D6: ~6 weeks per sign; Rx ~2 months
A7: Mercury | B7: Aquarius | C7: 14.9219 | D7: ~3–4 weeks; retrograde 3× per year
A8: Jupiter | B8: Gemini | C8: 20.9244 | D8: ~1 year per sign — major timing
A9: Venus | B9: Pisces | C9: 19.179 | D9: ~3–4 weeks; Rx every 18 months
A10: Saturn | B10: Pisces | C10: 9.484 | D10: ~2.5 years per sign — most impactful
A11: Rahu | B11: Aquarius | C11: 13.9637 | D11: ~18 months per sign (always retrograde)
A12: Ketu | B12: Leo | C12: 13.9637 | D12: Always 7 signs from Rahu
A14: Analysis date | B14: =TODAY() -> 46100
B15: 17-Mar-2026 11:14

Sheet INPUT_Chart_Scenario
A1: INPUT_Chart_Scenario · What-If Chart · Change any planet position to model alternative placements | L1: =HYPERLINK("#'00_INDEX'!A1","<- Index") -> <- Index
A2: ⚡ SCENARIO MODE: Change any Sign or Degree below. Activate scenario scoring via REF_Config toggle (Scenario mode = row 18). All SCORE_H sheets with scenario formulas will re-run from this chart.
A3: =IFERROR(IF(COUNTIF(CALC_PlanetLongitudes!$H$7:$H$16,"<>")>0,"BOUNDARY ALERT: "&COUNTIF(CALC_PlanetLongitudes!$H$7:$H$16,"<>")&" planet(s) near sign boundary - verify with third-party software",""),"") -> BOUNDARY ALERT: 10 planet(s) near sign boundary - verify with third-party software
A4: Planet / Point | B4: Valid Signs | C4: Sign Placed | D4: Degree (0-29) | E4: Sanskrit Name | F4: Notes
A5: Lagna (Ascendant) | B5: Aries,Taurus,Gemini,Cancer,Leo,Virgo,Libra,Scorpio,Sagittarius,Capricorn,Aquarius,Pisces | C5: =INPUT_Chart!C5 -> Taurus | D5: =INPUT_Chart!D5 -> 7.7286 | E5: Mesh | F5: Rising sign — most important input
A6: Sun / Surya | B6: Aries,Taurus,Gemini,Cancer,Leo,Virgo,Libra,Scorpio,Sagittarius,Capricorn,Aquarius,Pisces | C6: =INPUT_Chart!C6 -> Cancer | D6: =INPUT_Chart!D6 -> 27.989 | E6: Surya | F6: Soul, father, authority
A7: Moon / Chandramaa | B7: Aries,Taurus,Gemini,Cancer,Leo,Virgo,Libra,Scorpio,Sagittarius,Capricorn,Aquarius,Pisces | C7: =INPUT_Chart!C7 -> Cancer | D7: =INPUT_Chart!D7 -> 3.9835 | E7: Chandramaa | F7: Mind, mother, emotions
A8: Mars / Mangal | B8: Aries,Taurus,Gemini,Cancer,Leo,Virgo,Libra,Scorpio,Sagittarius,Capricorn,Aquarius,Pisces | C8: =INPUT_Chart!C8 -> Gemini | D8: =INPUT_Chart!D8 -> 7.4562 | E8: Mangal | F8: Energy, siblings, courage
A9: Mercury / Budh | B9: Aries,Taurus,Gemini,Cancer,Leo,Virgo,Libra,Scorpio,Sagittarius,Capricorn,Aquarius,Pisces | C9: =INPUT_Chart!C9 -> Cancer | D9: =INPUT_Chart!D9 -> 13.6743 | E9: Budh | F9: Intellect, communication
A10: Jupiter / Brihaspati | B10: Aries,Taurus,Gemini,Cancer,Leo,Virgo,Libra,Scorpio,Sagittarius,Capricorn,Aquarius,Pisces | C10: =INPUT_Chart!C10 -> Libra | D10: =INPUT_Chart!D10 -> 25.8777 | E10: Brihaspati | F10: Wisdom, children, fortune
A11: Venus / Shukra | B11: Aries,Taurus,Gemini,Cancer,Leo,Virgo,Libra,Scorpio,Sagittarius,Capricorn,Aquarius,Pisces | C11: =INPUT_Chart!C11 -> Cancer | D11: =INPUT_Chart!D11 -> 22.5612 | E11: Shukra | F11: Love, luxury, relationships
A12: Saturn / Shani | B12: Aries,Taurus,Gemini,Cancer,Leo,Virgo,Libra,Scorpio,Sagittarius,Capricorn,Aquarius,Pisces | C12: =INPUT_Chart!C12 -> Cancer | D12: =INPUT_Chart!D12 -> 20.473 | E12: Shani | F12: Discipline, karma, longevity
A13: Rahu (N. Node) | B13: Aries,Taurus,Gemini,Cancer,Leo,Virgo,Libra,Scorpio,Sagittarius,Capricorn,Aquarius,Pisces | C13: =INPUT_Chart!C13 -> Taurus | D13: =INPUT_Chart!D13 -> 5.0697 | E13: Rahu | F13: Obsession, amplifier — no own sign
A14: Ketu (S. Node) | B14: Aries,Taurus,Gemini,Cancer,Leo,Virgo,Libra,Scorpio,Sagittarius,Capricorn,Aquarius,Pisces | C14: =INPUT_Chart!C14 -> Scorpio | D14: =INPUT_Chart!D14 -> 5.0697 | E14: Ketu | F14: Detachment — always 7 signs from Rahu
A16: Moon longitude (for Dasha) | B16: Auto-reads sign+degree from row 7 above | C16: =IFERROR("≈ "&TEXT((MATCH(C7,{"Aries","Taurus","Gemini","Cancer","Leo","Virgo","Libra","Scorpio","Sagittarius","Capricorn","Aquarius","Pisces"},0)-1)*30+D7,"0.00")&"° abs","Enter Moon sign+degree above") -> ≈ 93.98° abs | D16: Used in INPUT_BirthData Dasha calc | E16: Chandramaa | F16: Auto-computed from Moon row — no extra entry needed
A17: REFERENCE: Shubh (Benefic) and Ashubh (Malefic) planets change based on Lagna — see REF_ShubhAshubh sheet

Sheet REF_Zodiac
A1: REF_Zodiac — Complete Jyotish Zodiac Reference · Sources: BPHS, Saravali, Phaladeepika | Q1: =HYPERLINK("#'00_INDEX'!A1","<- Index") -> <- Index
A2: READ-ONLY reference table — never edit directly. All CALC_ sheets look up values here via INDEX/MATCH on the sign name. Blue = scoring flags used by SCORE_AllHouses.
A3: Group | B3: Attribute | C3: Sanskrit | D3: Aries | E3: Taurus | F3: Gemini | G3: Cancer | H3: Leo | I3: Virgo | J3: Libra | K3: Scorpio | L3: Sagittarius | M3: Capricorn | N3: Aquarius | O3: Pisces
A4: Identity | B4: Sanskrit / Rashi | C4: Rashi | D4: Mesh | E4: Vrishabh | F4: Mithun | G4: Kark | H4: Simh | I4: Kanya | J4: Tula | K4: Vrishchik | L4: Dhanu | M4: Makar | N4: Kumbh | O4: Meen
B5: Sign number | C5: Rashi Krama | D5: 1 | E5: 2 | F5: 3 | G5: 4 | H5: 5 | I5: 6 | J5: 7 | K5: 8 | L5: 9 | M5: 10 | N5: 11 | O5: 12
B6: Symbol | C6: Pratik | D6: Ram | E6: Bull | F6: Twins | G6: Crab | H6: Lion | I6: Virgin | J6: Scales | K6: Scorpion | L6: Archer | M6: Sea-goat | N6: Water-bearer | O6: Fish
A7: Lordship | B7: Ruling planet | C7: Swami / Adhipati | D7: Mars | E7: Venus | F7: Mercury | G7: Moon | H7: Sun | I7: Mercury | J7: Venus | K7: Mars | L7: Jupiter | M7: Saturn | N7: Saturn | O7: Jupiter
B8: Ruling planet (Skt) | C8: Graha Swami | D8: Mangal | E8: Shukra | F8: Budh | G8: Chandramaa | H8: Surya | I8: Budh | J8: Shukra | K8: Mangal | L8: Brihaspati | M8: Shani | N8: Shani | O8: Brihaspati
B9: Exaltation planet | C9: Uchcha Graha | D9: Sun | E9: Moon | F9: — | G9: Jupiter | H9: — | I9: Mercury | J9: Saturn | K9: — | L9: — | M9: Mars | N9: — | O9: Venus
B10: Exaltation degree | C10: Uchcha Amsha | D10: 10° | E10: 3° | F10: — | G10: 5° | H10: — | I10: 15° | J10: 20° | K10: — | L10: — | M10: 28° | N10: — | O10: 27°
B11: Debilitation planet | C11: Neecha Graha | D11: Saturn | E11: — | F11: — | G11: Mars | H11: — | I11: Venus | J11: Sun | K11: — | L11: — | M11: Jupiter | N11: — | O11: Mercury
B12: Mooltrikona sign of | C12: Mooltrikona | D12: Mars (0–18°) | E12: Venus (0–15°) | F12: Mercury (0–15°) | G12: — | H12: Sun (0–20°) | I12: Mercury (16–20°) | J12: Saturn (0–20°) | K12: — | L12: Jupiter (0–10°) | M12: — | N12: — | O12: —
A13: Nature | B13: Element / Tattva | C13: Tattva | D13: Fire | E13: Earth | F13: Air | G13: Water | H13: Fire | I13: Earth | J13: Air | K13: Water | L13: Fire | M13: Earth | N13: Air | O13: Water
B14: Modality | C14: Chara/Sthir/Dwi | D14: Movable / Char | E14: Fixed / Sthir | F14: Dual / Dwiswabhav | G14: Movable / Char | H14: Fixed / Sthir | I14: Dual / Dwiswabhav | J14: Movable / Char | K14: Fixed / Sthir | L14: Dual / Dwiswabhav | M14: Movable / Char | N14: Fixed / Sthir | O14: Dual / Dwiswabhav
B15: Gender | C15: Strī/Purusha | D15: Masculine | E15: Feminine | F15: Masculine | G15: Feminine | H15: Masculine | I15: Feminine | J15: Masculine | K15: Feminine | L15: Masculine | M15: Feminine | N15: Masculine | O15: Feminine
B16: Sign type | C16: Rashi Prakriti | D16: Odd / Vishama | E16: Even / Sama | F16: Odd / Vishama | G16: Even / Sama | H16: Odd / Vishama | I16: Even / Sama | J16: Odd / Vishama | K16: Even / Sama | L16: Odd / Vishama | M16: Even / Sama | N16: Odd / Vishama | O16: Even / Sama
A17: Temperament | B17: Temperament | C17: Swabhava | D17: Cruel | E17: Gentle | F17: Gentle | G17: Gentle | H17: Cruel | I17: Gentle | J17: Gentle | K17: Cruel | L17: Gentle | M17: Cruel | N17: Cruel | O17: Gentle
B18: Body type | C18: Deha Prakriti | D18: Biped | E18: Quadruped | F18: Biped | G18: Aquatic | H18: Quadruped | I18: Biped | J18: Biped | K18: Insect / Reptile | L18: Biped (half) / Quadruped (half) | M18: Aquatic / Quadruped | N18: Biped | O18: Aquatic
B19: Fertility | C19: Santan Shakti | D19: Barren | E19: Fruitful | F19: Barren | G19: Fruitful | H19: Barren | I19: Barren | J19: Semi-fruitful | K19: Fruitful | L19: Semi-fruitful | M19: Semi-fruitful | N19: Barren | O19: Fruitful
B20: Voice quality | C20: Vak Bala | D20: Strong voice | E20: Strong voice | F20: Dual voice | G20: Mute / Silent | H20: Strong voice | I20: Dual voice | J20: Dual voice | K20: Mute / Silent | L20: Strong voice | M20: Mute / Silent | N20: Strong voice | O20: Mute / Silent
A21: Dosha / Guna | B21: Ayurvedic dosha | C21: Tridosha | D21: Pitta | E21: Vata / Kapha | F21: Vata / Pitta | G21: Kapha | H21: Pitta / Kapha | I21: Vata / Pitta | J21: Vata / Kapha | K21: Kapha / Pitta | L21: Pitta / Vata | M21: Vata / Kapha | N21: Vata | O21: Kapha
B22: Triguna | C22: Guna | D22: Rajas | E22: Tamas | F22: Rajas | G22: Sattva | H22: Sattva | I22: Tamas | J22: Rajas | K22: Tamas | L22: Sattva | M22: Tamas | N22: Tamas | O22: Sattva
B23: Body substance | C23: Dhatu / Jeev / Mool | D23: Dhatu (minerals) | E23: Dhatu (minerals) | F23: Jeev (living) | G23: Jeev (living) | H23: Jeev (living) | I23: Jeev (living) | J23: Jeev (living) | K23: Jeev (living) | L23: Jeev (living) | M23: Jeev (living) | N23: Dhatu (minerals) | O23: Mool (plants)
A24: Social | B24: Varna (caste) | C24: Varna | D24: Kshatriya | E24: Vaishya | F24: Shudra | G24: Brahmin | H24: Kshatriya | I24: Vaishya | J24: Shudra | K24: Brahmin | L24: Kshatriya | M24: Vaishya | N24: Shudra | O24: Brahmin
A25: Directional | B25: Direction | C25: Disha | D25: East / Purva | E25: South / Dakshina | F25: West / Paschima | G25: North / Uttara | H25: East / Purva | I25: South / Dakshina | J25: West / Paschima | K25: North / Uttara | L25: East / Purva | M25: South / Dakshina | N25: West / Paschima | O25: North / Uttara
A26: Physical | B26: Colour | C26: Rang | D26: Red / Blood red | E26: White / Off-white | F26: Green | G26: Pale / Pinkish | H26: Golden / Wheatish | I26: Multi-coloured / Spotted | J26: Black / Variegated | K26: Brown / Reddish | L26: Yellow / Golden | M26: Variegated / Dark | N26: Blue / Black | O26: Off-white / Sea green
B27: Body part (Kalapurusha) | C27: Kalapurusha Anga | D27: Head / Skull | E27: Face / Neck / Throat | F27: Shoulders / Arms / Hands | G27: Chest / Heart / Lungs | H27: Stomach / Back / Spine | I27: Waist / Lower abdomen / Intestines | J27: Kidneys / Lower back / Navel | K27: Genitals / Rectum / Bladder | L27: Thighs / Hips / Liver | M27: Knees / Joints / Bones | N27: Ankles / Calves / Circulatory system | O27: Feet / Lymphatic system / Immune system
A28: Technical | B28: Rising direction | C28: Udaya Prakar | D28: Shirshodaya (head first) | E28: Prishtodaya (back first) | F28: Shirshodaya | G28: Prishtodaya | H28: Shirshodaya | I28: Shirshodaya | J28: Shirshodaya | K28: Prishtodaya | L28: Shirshodaya | M28: Prishtodaya | N28: Shirshodaya | O28: Ubhayodaya (both ways)
B29: Strength period | C29: Bala Kaal | D29: Night | E29: Day | F29: Night | G29: Night | H29: Day | I29: Day | J29: Day | K29: Night | L29: Day | M29: Night | N29: Day | O29: Night
B30: Seasonal strength | C30: Ritu Bala | D30: Vasanta (Spring) | E30: Grishma (Summer) | F30: Grishma (Summer) | G30: Varsha (Rains) | H30: Varsha (Rains) | I30: Sharad (Autumn) | J30: Sharad (Autumn) | K30: Hemanta (Early winter) | L30: Hemanta (Early winter) | M30: Shishira (Winter) | N30: Shishira (Winter) | O30: Vasanta (Spring)
A31: Classification | B31: Natural house type | C31: Bhav Prakar | D31: Kendra | E31: Dhan / 2nd | F31: Upachaya | G31: Kendra / Sukha | H31: Trikon | I31: Upachaya / Roga | J31: Kendra / Kalatra | K31: Randhra / Ayu | L31: Trikon / Bhagya | M31: Kendra / Karma | N31: Labha | O31: Vyaya
B32: House group | C32: Bhav Varga | D32: Angular | E32: Succedent | F32: Cadent | G32: Angular | H32: Succedent | I32: Cadent | J32: Angular | K32: Succedent | L32: Cadent | M32: Angular | N32: Succedent | O32: Cadent
A33: Technical | B33: Nakshatras spanning | C33: Nakshatra Span | D33: Ashwini, Bharani, Krittika (1) | E33: Krittika (2-4), Rohini, Mrigashira (1-2) | F33: Mrigashira (3-4), Ardra, Punarvasu (1-3) | G33: Punarvasu (4), Pushya, Ashlesha | H33: Magha, Purva Phalguni, Uttara Phalguni (1) | I33: Uttara Phalguni (2-4), Hasta, Chitra (1-2) | J33: Chitra (3-4), Swati, Vishakha (1-3) | K33: Vishakha (4), Anuradha, Jyeshtha | L33: Mula, Purva Ashadha, Uttara Ashadha (1) | M33: Uttara Ashadha (2-4), Shravana, Dhanishtha (1-2) | N33: Dhanishtha (3-4), Shatabhisha, Purva Bhadrapada (1-3) | O33: Purva Bhadrapada (4), Uttara Bhadrapada, Revati
A34: Karakatva | B34: Primary Karak planet | C34: Mukhya Karak | D34: Mars (energy, self) | E34: Venus (beauty, wealth) | F34: Mercury (communication) | G34: Moon (mind, mother) | H34: Sun (soul, authority) | I34: Mercury (analysis, health) | J34: Venus (relationships, balance) | K34: Mars / Saturn (transformation) | L34: Jupiter (dharma, expansion) | M34: Saturn (career, discipline) | N34: Saturn / Rahu (gains, groups) | O34: Jupiter (liberation, isolation)
A35: Scoring flags | B35: Dukshthan (6/8/12)? | C35: Dukh Sthana | D35: No | E35: No | F35: No | G35: No | H35: No | I35: Yes (6th) | J35: No | K35: Yes (8th) | L35: No | M35: No | N35: No | O35: Yes (12th)
B36: Kendra (1/4/7/10)? | C36: Kendra | D36: Yes (1st) | E36: No | F36: No | G36: Yes (4th) | H36: No | I36: No | J36: Yes (7th) | K36: No | L36: No | M36: Yes (10th) | N36: No | O36: No
B37: Trikon (1/5/9)? | C37: Trikon | D37: Yes (1st) | E37: No | F37: No | G37: No | H37: Yes (5th) | I37: No | J37: No | K37: No | L37: Yes (9th) | M37: No | N37: No | O37: No
B38: Upachaya (3/6/10/11)? | C38: Upachaya | D38: No | E38: No | F38: Yes (3rd) | G38: No | H38: No | I38: Yes (6th) | J38: No | K38: No | L38: No | M38: Yes (10th) | N38: Yes (11th) | O38: No
A39: Source: Brihat Parashara Hora Shastra (BPHS) Ch.3-4 · Saravali Ch.2 · Phaladeepika Ch.1 · Cross-checked with Jagannatha Hora software output

Sheet REF_Zodiac_Lookup
A1: REF_Zodiac_Lookup — Formula patterns for CALC_ sheets | L1: =HYPERLINK("#'00_INDEX'!A1","<- Index") -> <- Index
A2: Copy these formula patterns into CALC_PlanetPositions or any sheet that needs to look up a sign's properties. Replace B5 with the cell containing the sign name.
A4: Attribute wanted | B4: Formula to use | C4: Returns | D4: Notes
A5: Element / Tattva | B5: Aries | C5: Fire / Earth / Air / Water | D5: Replace B5 with any cell containing a sign name
A6: Ruling planet | B6: =IFERROR(INDEX(REF_Zodiac!$D$7:$O$7,MATCH(B5,REF_Zodiac!$D$3:$O$3,0)),"") -> Mars | C6: Mars / Venus / Mercury… | D6: Use for Bhavesh (house lord) identification
A7: Modality | B7: =IFERROR(INDEX(REF_Zodiac!$D$14:$O$14,MATCH(B5,REF_Zodiac!$D$3:$O$3,0)),"") -> Movable / Char | C7: Movable / Fixed / Dual | D7: Used in Chara/Sthira Karak assessments
A8: Exaltation planet | B8: =IFERROR(INDEX(REF_Zodiac!$D$9:$O$9,MATCH(B5,REF_Zodiac!$D$3:$O$3,0)),"") -> Sun | C8: Sun / Moon / Mars… | D8: Check if a planet placed here is exalted
A9: Temperament | B9: =IFERROR(INDEX(REF_Zodiac!$D$17:$O$17,MATCH(B5,REF_Zodiac!$D$3:$O$3,0)),"") -> Cruel | C9: Cruel / Gentle | D9: Cruel signs (1/5/8/10/11) reduce benefic effects
A10: Dukshthan? | B10: =IFERROR(INDEX(REF_Zodiac!$D$35:$O$35,MATCH(B5,REF_Zodiac!$D$3:$O$3,0)),"") -> No | C10: Yes (6th) / No | D10: Used in Bhavesh_Durbal Rule #15 check
A11: Kendra? | B11: =IFERROR(INDEX(REF_Zodiac!$D$36:$O$36,MATCH(B5,REF_Zodiac!$D$3:$O$3,0)),"") -> Yes (1st) | C11: Yes (1st) / No | D11: Kendra placement = strong position for Bhavesh_Bal
A12: Trikon? | B12: =IFERROR(INDEX(REF_Zodiac!$D$37:$O$37,MATCH(B5,REF_Zodiac!$D$3:$O$3,0)),"") -> Yes (1st) | C12: Yes (5th) / No | D12: Trikon placement = auspicious. 1/5/9 houses.
A13: Varna | B13: =IFERROR(INDEX(REF_Zodiac!$D$24:$O$24,MATCH(B5,REF_Zodiac!$D$3:$O$3,0)),"") -> Kshatriya | C13: Brahmin / Kshatriya… | D13: Used in Varna compatibility matching
A14: Direction | B14: =IFERROR(INDEX(REF_Zodiac!$D$25:$O$25,MATCH(B5,REF_Zodiac!$D$3:$O$3,0)),"") -> East / Purva | C14: East / South / West / North | D14: Directional strength (Dig Bala) calculations
A15: Body part | B15: =IFERROR(INDEX(REF_Zodiac!$D$27:$O$27,MATCH(B5,REF_Zodiac!$D$3:$O$3,0)),"") -> Head / Skull | C15: Head / Neck / Arms… | D15: Medical astrology — afflictions to this house affect this body part
A16: Nakshatras spanning | B16: =IFERROR(INDEX(REF_Zodiac!$D$33:$O$33,MATCH(B5,REF_Zodiac!$D$3:$O$3,0)),"") -> Ashwini, Bharani, Krittika (1) | C16: Ashwini, Bharani, Krittika (1) | D16: Cross-reference with REF_Nakshatra for sub-lord calculations
A19: INDEX(REF_Zodiac!$D$row:$O$row, MATCH(sign_cell, REF_Zodiac!$D$3:$O$3, 0))

Sheet REF_Planets
A1: REF_Planets — Complete Jyotish Planet Reference · Sources: BPHS Ch.3, Saravali Ch.1, Phaladeepika Ch.2 | M1: =HYPERLINK("#'00_INDEX'!A1","<- Index") -> <- Index
A2: READ-ONLY — all CALC_ sheets look up values here via INDEX/MATCH on the planet name. Rahu/Ketu are shadow nodes: no own signs in classical sense, always retrograde, amplify whatever they conjoin.
A3: Section | B3: Attribute | C3: Sanskrit | D3: Sun | E3: Moon | F3: Mars | G3: Mercury | H3: Jupiter | I3: Venus | J3: Saturn | K3: Rahu | L3: Ketu
A4: Identity | B4: Planet (English) | C4: Graha | D4: Sun | E4: Moon | F4: Mars | G4: Mercury | H4: Jupiter | I4: Venus | J4: Saturn | K4: Rahu | L4: Ketu
B5: Sanskrit name | C5: Sanskrit | D5: Surya | E5: Chandramaa | F5: Mangal | G5: Budh | H5: Brihaspati | I5: Shukra | J5: Shani | K5: Rahu | L5: Ketu
B6: Also known as | C6: Upanaam | D6: Aditya / Ravi | E6: Soma / Indu | F6: Kuja / Angaraka | G6: Soumya | H6: Guru / Devaguru | I6: Bhrigu / Sita | J6: Manda / Yama | K6: Swarbhanu (head) | L6: Swarbhanu (tail)
B7: Planet type | C7: Graha Prakar | D7: Luminaries | E7: Luminaries | F7: Inner planets | G7: Inner planets | H7: Outer planets | I7: Inner planets | J7: Outer planets | K7: Shadow node | L7: Shadow node
B8: Dasha order # | C8: Dasha Krama | D8: 3 | E8: 4 | F8: 7 | G8: 6 | H8: 5 | I8: 2 | J8: 8 | K8: 1 | L8: 9
B9: Dasha years | C9: Dasha Varsha | D9: 6 | E9: 10 | F9: 7 | G9: 17 | H9: 16 | I9: 20 | J9: 19 | K9: 18 | L9: 7
B10: Orbital speed | C10: Gati | D10: ~1°/day | E10: ~13°/day | F10: ~0.5°/day | G10: ~1.5°/day | H10: ~0.08°/day | I10: ~1.2°/day | J10: ~0.03°/day | K10: ~0.05°/day (mean) | L10: ~0.05°/day (mean)
A11: Lordship | B11: Own sign #1 | C11: Swarashi #1 | D11: Leo | E11: Cancer | F11: Aries | G11: Gemini | H11: Sagittarius | I11: Taurus | J11: Capricorn | K11: Aquarius | L11: Scorpio
B12: Own sign #2 | C12: Swarashi #2 | D12: — | E12: — | F12: Scorpio | G12: Virgo | H12: Pisces | I12: Libra | J12: Aquarius | K12: — | L12: —
B13: Exaltation sign | C13: Uchcha Rashi | D13: Aries | E13: Taurus | F13: Capricorn | G13: Virgo | H13: Cancer | I13: Pisces | J13: Libra | K13: Taurus | L13: Scorpio
B14: Exaltation degree | C14: Uchcha Amsha | D14: 10° | E14: 3° | F14: 28° | G14: 15° | H14: 5° | I14: 27° | J14: 20° | K14: 20° | L14: —
B15: Debilitation sign | C15: Neecha Rashi | D15: Libra | E15: Scorpio | F15: Cancer | G15: Pisces | H15: Capricorn | I15: Virgo | J15: Aries | K15: Scorpio | L15: Taurus
B16: Debilitation degree | C16: Neecha Amsha | D16: 10° | E16: 3° | F16: 28° | G16: 15° | H16: 5° | I16: 27° | J16: 20° | K16: 20° | L16: —
B17: Mooltrikona sign | C17: Mooltrikona Rashi | D17: Leo (0–20°) | E17: Taurus (4–20°) | F17: Aries (0–12°) | G17: Virgo (16–20°) | H17: Sagittarius (0–10°) | I17: Libra (0–15°) | J17: Aquarius (0–20°) | K17: — | L17: —
B18: Combust orb | C18: Asta Orb | D18: — | E18: 12° | F18: 17° | G18: 14° | H18: 11° | I18: 10° | J18: 15° | K18: — | L18: —
A19: Nature | B19: Natural nature | C19: Naisargika Swabhav | D19: Malefic | E19: Benefic (waxing) / Malefic (waning) | F19: Malefic | G19: Benefic (with benefics) / Malefic (with malefics) | H19: Benefic | I19: Benefic | J19: Malefic | K19: Malefic | L19: Malefic
B20: Gender | C20: Linga | D20: Masculine | E20: Feminine | F20: Masculine | G20: Neutral | H20: Masculine | I20: Feminine | J20: Neutral / Masculine | K20: Feminine | L20: Neutral
B21: Element / Tattva | C21: Tattva | D21: Fire | E21: Water | F21: Fire | G21: Earth | H21: Ether / Akash | I21: Water | J21: Air | K21: Air | L21: Fire
B22: Triguna | C22: Guna | D22: Sattva | E22: Sattva | F22: Tamas | G22: Rajas | H22: Sattva | I22: Rajas | J22: Tamas | K22: Tamas | L22: Tamas
B23: Varna | C23: Varna | D23: Kshatriya | E23: Vaishya | F23: Kshatriya | G23: Shudra | H23: Brahmin | I23: Brahmin | J23: Shudra | K23: Outcaste | L23: Outcaste
B24: Temperament | C24: Swabhava | D24: Steady / Fixed | E24: Changeable / Fickle | F24: Angry / Violent | G24: Humorous / Speech | H24: Benign / Mild | I24: Soft-hearted / Accommodating | J24: Subordinate / Servant | K24: Cruel / Unpredictable | L24: Cruel / Unpredictable
B25: Caste quality | C25: Jati | D25: Kshatriya | E25: Vaishya | F25: Kshatriya | G25: Shudra | H25: Brahmin | I25: Brahmin | J25: Shudra | K25: Low caste | L25: Low caste
A26: Karakatva | B26: Primary significations | C26: Mukhya Karakatva | D26: Soul, father, authority, vitality, self-confidence, government, power | E26: Mind, mother, emotions, nourishment, memory, response, sensitivity, public | F26: Bravery, aggression, courage, siblings, energy, accidents, surgery, property | G26: Speech, intelligence, analysis, communication, trade, education, writing, skin | H26: Wisdom, children, fortune, dharma, expansion, optimism, knowledge, teachers, law | I26: Harmony, love, beauty, luxury, relationships, arts, vehicles, pleasure, spouse | J26: Hard work, karma, longevity, discipline, delay, sorrow, service, old age, teeth | K26: Explosiveness, obsession, foreign, illusion, unconventional, materialistic gains, paternal grandfather | L26: Detachment, liberation, spirituality, intuition, transformation, elimination, maternal grandparents
B27: Sthir Karak for house | C27: Sthir Karak Bhav | D27: H1 (self), H9 (father), H10 (career) | E27: H4 (mother), H4 (mind / emotions) | F27: H3 (siblings / courage), H6 (enemies) | G27: H4 (education), H10 (business) | H27: H2 (wealth), H5 (children), H9 (fortune), H11 (gains) | I27: H2 (speech), H7 (spouse / marriage) | J27: H6 (service / disease), H8 (longevity), H10 (karma) | K27: H6 (obstacles), H12 (foreign / isolation) | L27: H12 (liberation / moksha)
B28: Cabinet role | C28: Rajdarbar | D28: King | E28: Queen | F28: Commander-in-chief | G28: Crown Prince / Yuvaraja | H28: Minister / Advisor | I28: Minister / Advisor (Royal) | J28: Servant | K28: — | L28: —
B29: Relationship signified | C29: Sambandh | D29: Father / Authority | E29: Mother / Public | F29: Younger siblings / Soldiers | G29: Maternal uncle / Friends | H29: Teachers / Elders / Husband (for women) | I29: Wife / Sisters / Young women | J29: Servant / Old people / Outcaste | K29: Paternal grandfather / Foreigners | L29: Maternal grandparents / Ascetics
A30: Body | B30: Body parts ruled | C30: Sharira Anga | D30: Bones (Asthi), Right eye, Heart, Stomach, Head (crown) | E30: Blood (Rakta), Left eye, Lungs, Breasts, Mind | F30: Muscles (Mamsa), Bone marrow, Blood, Bile, Head (forehead) | G30: Skin (Tvak), Nerves, Lungs, Speech organs, Hands | H30: Fat (Meda), Brain, Liver, Thighs, Ears | I30: Semen / Reproductive fluids, Skin, Genitals, Eyes (vision), Kidneys | J30: Tendons / Cartilage, Nerves (coarser), Teeth, Legs (feet / shins) | K30: Digestive system (general), Skin diseases, Nervous system disorders | L30: Feet, Spiritual body, Subtle nervous system
B31: Ayurvedic tissue | C31: Dhatu | D31: Bone (Asthi) | E31: Blood (Rakta) | F31: Muscle (Mamsa) | G31: Skin (Tvak) | H31: Fat (Meda) | I31: Semen / Shukra | J31: Nerves / Tendons | K31: Mixed / Vata | L31: Mixed / Vata
B32: Ayurvedic dosha | C32: Tridosha | D32: Pitta | E32: Vata / Kapha | F32: Pitta / Vata | G32: Vata / Pitta | H32: Kapha | I32: Kapha / Vata | J32: Vata | K32: Vata | L32: Vata / Pitta
B33: Taste / Rasa | C33: Rasa | D33: Pungent / Tikta | E33: Saline / Namkeen | F33: Bitter / Kadwa | G33: Mixed / Chatpata | H33: Sweet / Meetha | I33: Sour / Khatta | J33: Astringent / Kacha | K33: Mixed | L33: Mixed
B34: Diseases indicated | C34: Roga | D34: Heart disease, fever, eye problems, bone issues, blood pressure | E34: Mental issues, cold/cough, anaemia, menstrual disorders, water retention | F34: Accidents, wounds, burns, inflammation, blood disorders, surgery | G34: Skin diseases, nervous disorders, speech problems, respiratory issues | H34: Liver problems, obesity, diabetes, tumours, ear troubles | I34: Reproductive disorders, diabetes, STDs, kidney issues, hormonal imbalance | J34: Chronic illness, paralysis, arthritis, teeth, dental issues, cold diseases | K34: Skin diseases, nervous breakdown, obsessive disorders, poisoning | L34: Mysterious diseases, spiritual crises, leprosy, past-life karma
A35: Relationships | B35: Natural friends | C35: Naisargika Mitra | D35: Moon, Mars, Jupiter | E35: Sun, Mercury | F35: Sun, Moon, Jupiter | G35: Sun, Venus | H35: Sun, Moon, Mars | I35: Mercury, Saturn | J35: Mercury, Venus | K35: Venus, Saturn | L35: Mars, Venus
B36: Natural neutrals | C36: Naisargika Sama | D36: Mercury | E36: Mars, Jupiter, Venus, Saturn | F36: Venus, Saturn | G36: Mars, Jupiter, Saturn | H36: Saturn | I36: Jupiter, Mars | J36: Jupiter | K36: Ketu, Jupiter | L36: Rahu, Sun, Moon
B37: Natural enemies | C37: Naisargika Shatru | D37: Venus, Saturn | E37: Rahu, Ketu | F37: Mercury | G37: Moon | H37: Mercury, Venus | I37: Sun, Moon | J37: Sun, Moon, Mars | K37: Sun, Moon, Mars | L37: Saturn, Mercury
A38: Mundane | B38: Direction (Dig Bala) | C38: Disha | D38: South | E38: North | F38: South | G38: North | H38: East | I38: East | J38: West | K38: South-West | L38: North-East
B39: Dig Bala house | C39: Dig Bala Sthana | D39: H10 | E39: H4 | F39: H10 / H3 | G39: H1 | H39: H1 / H9 | I39: H4 | J39: H7 | K39: H3 | L39: H9
B40: Day/Night strength | C40: Diva / Ratri Bali | D40: Day | E40: Night | F40: Night | G40: Day | H40: Day | I40: Night | J40: Night | K40: Night | L40: Night
...

Sheet REF_Planets_Lookup
A1: REF_Planets_Lookup — INDEX/MATCH formulas for CALC_ sheets | L1: =HYPERLINK("#'00_INDEX'!A1","<- Index") -> <- Index
A2: Pattern: =INDEX(REF_Planets!$D$ROW:$L$ROW, MATCH(planet_cell, REF_Planets!$D$3:$L$3, 0)) where ROW = attribute row number below. Replace planet_cell with e.g. CALC_PlanetPositions!B5
A4: Attribute | B4: Formula | C4: Returns | D4: Use in
A5: Own sign #1 | B5: =IFERROR(INDEX(REF_Planets!$D$11:$L$11,MATCH(planet_cell,REF_Planets!$D$4:$L$4,0)),"") | C5: Row 11 in REF_Planets | D5: CALC_BhaveshMap — identify lord of each house
A6: Exaltation sign | B6: =IFERROR(INDEX(REF_Planets!$D$13:$L$13,MATCH(planet_cell,REF_Planets!$D$4:$L$4,0)),"") | C6: Row 13 in REF_Planets | D6: CALC_PlanetPositions — check if planet is exalted in its current sign
A7: Debilitation sign | B7: =IFERROR(INDEX(REF_Planets!$D$15:$L$15,MATCH(planet_cell,REF_Planets!$D$4:$L$4,0)),"") | C7: Row 15 in REF_Planets | D7: CALC_PlanetPositions — check if planet is debilitated
A8: Mooltrikona sign | B8: =IFERROR(INDEX(REF_Planets!$D$17:$L$17,MATCH(planet_cell,REF_Planets!$D$4:$L$4,0)),"") | C8: Row 17 in REF_Planets | D8: CALC_PlanetPositions — dignity level between own and exalt
A9: Natural nature | B9: =IFERROR(INDEX(REF_Planets!$D$19:$L$19,MATCH(planet_cell,REF_Planets!$D$4:$L$4,0)),"") | C9: Row 19 in REF_Planets | D9: REF_ShubhAshubh — base classification before Lagna modification
A10: Dasha years | B10: =IFERROR(INDEX(REF_Planets!$D$9:$L$9,MATCH(planet_cell,REF_Planets!$D$4:$L$4,0)),"") | C10: Row 9 in REF_Planets | D10: INPUT_BirthData — Vimshottari timeline calculation
A11: Special aspects | B11: =IFERROR(INDEX(REF_Planets!$D$48:$L$48,MATCH(planet_cell,REF_Planets!$D$4:$L$4,0)),"") | C11: Row 48 in REF_Planets | D11: CALC_PlanetPositions — which houses each planet aspects
A12: Combust orb | B12: =IFERROR(INDEX(REF_Planets!$D$18:$L$18,MATCH(planet_cell,REF_Planets!$D$4:$L$4,0)),"") | C12: Row 18 in REF_Planets | D12: CALC_PlanetPositions — is a planet within Sun's orb → combusted?
A13: Natural friends | B13: =IFERROR(INDEX(REF_Planets!$D$35:$L$35,MATCH(planet_cell,REF_Planets!$D$4:$L$4,0)),"") | C13: Row 35 in REF_Planets | D13: CALC_PanchadhaMaitri — Naisargika friendship input
A14: Natural enemies | B14: =IFERROR(INDEX(REF_Planets!$D$37:$L$37,MATCH(planet_cell,REF_Planets!$D$4:$L$4,0)),"") | C14: Row 37 in REF_Planets | D14: CALC_PanchadhaMaitri — Naisargika enmity input
A15: Dig Bala house | B15: =IFERROR(INDEX(REF_Planets!$D$39:$L$39,MATCH(planet_cell,REF_Planets!$D$4:$L$4,0)),"") | C15: Row 39 in REF_Planets | D15: Future Shadbala — directional strength peak house
A16: Sthir Karak for house | B16: =IFERROR(INDEX(REF_Planets!$D$27:$L$27,MATCH(planet_cell,REF_Planets!$D$4:$L$4,0)),"") | C16: Row 27 in REF_Planets | D16: CALC_KarakMap — which planet is the fixed significator for which house
A17: Is shadow planet? | B17: =IFERROR(INDEX(REF_Planets!$D$49:$L$49,MATCH(planet_cell,REF_Planets!$D$4:$L$4,0)),"") | C17: Row 49 in REF_Planets | D17: All scoring — Rahu/Ketu need special-cased logic (no dignity, no combustion)
A18: Always retrograde? | B18: =IFERROR(INDEX(REF_Planets!$D$50:$L$50,MATCH(planet_cell,REF_Planets!$D$4:$L$4,0)),"") | C18: Row 50 in REF_Planets | D18: CALC_PlanetPositions — Rahu/Ketu are always Rx; skip retrograde bonus for them
A19: Amplifies conjunct? | B19: =IFERROR(INDEX(REF_Planets!$D$52:$L$52,MATCH(planet_cell,REF_Planets!$D$4:$L$4,0)),"") | C19: Row 52 in REF_Planets | D19: CALC_PlanetPositions — Rahu/Ketu amplify conjunct planet's effects

Sheet REF_Dignity
A1: REF_Dignity — Complete Dignity & Degree Ranges · Sources: BPHS Ch.3, Saravali Ch.1, Uttara Kalamrita Ch.2 | O1: =HYPERLINK("#'00_INDEX'!A1","<- Index") -> <- Index
A2: CALC_PlanetPositions looks up rows by planet name (col A) to resolve dignity level. Deep = within ±5° of exact degree. MLT = Mooltrikona. Neecha Bhanga conditions are in col N — check before applying debilitation penalty.
A3: Planet | B3: Sanskrit | C3: Exalt sign | D3: Exalt ° (peak) | E3: Deep exalt range (±5° of peak) | F3: Debil sign | G3: Debil ° (peak) | H3: Deep debil range (±5° of peak) | I3: Mooltrikona sign & range | J3: Own sign(s) — full range | K3: Friendly signs | L3: Neutral signs | M3: Combust orb (direct) | N3: Neecha Bhanga conditions
A4: Sun | B4: Surya | C4: Aries | D4: 10° | E4: Aries 5°–15° | F4: Libra | G4: 10° | H4: Libra 5°–15° | I4: Leo 0°–20° | J4: Leo 20°–30° (own) / 0°–20° (MLT) | K4: Aries, Cancer, Leo, Sagittarius | L4: Gemini | M4: N/A (node) | N4: • Lord of Libra (Venus) in Kendra from Lagna or Moon • Planet exalted in Libra (Saturn at 20° Libra) in Kendra • Sun in Libra with exalted planet in same sign
A5: Moon | B5: Chandramaa | C5: Taurus | D5: 3° | E5: Taurus 0°–8° | F5: Scorpio | G5: 3° | H5: Scorpio 0°–8° | I5: Taurus 4°–20° | J5: Cancer 0°–30° (Own sign) | K5: Taurus, Cancer, Leo, Libra, Sagittarius, Pisces | L5: Aries, Gemini, Virgo, Aquarius | M5: Direct: ±12.0° Rx: ±12.0° | N5: • Lord of Scorpio (Mars) in Kendra from Lagna or Moon • Jupiter exalted in Cancer in Kendra • Moon in Scorpio with Mars in Kendra from Lagna • Moon waxing (Shukla Paksha) reduces debilitation effect
A6: Mars | B6: Mangal | C6: Capricorn | D6: 28° | E6: Capricorn 23°–29° | F6: Cancer | G6: 28° | H6: Cancer 23°–29° | I6: Aries 0°–12° | J6: Aries 12°–30° (own) / 0°–12° (MLT) Scorpio 0°–30° (Own sign) | K6: Aries, Leo, Sagittarius, Scorpio, Capricorn, Pisces | L6: Taurus, Virgo, Libra, Aquarius | M6: Direct: ±17.0° Rx: ±17.0° | N6: • Lord of Cancer (Moon) in Kendra from Lagna or Moon • Jupiter exalted in Cancer in Kendra • Mars itself in Capricorn (own exaltation sign lord Saturn in Kendra)
A7: Mercury | B7: Budh | C7: Virgo | D7: 15° | E7: Virgo 10°–20° | F7: Pisces | G7: 15° | H7: Pisces 10°–20° | I7: Virgo 0°–15° | J7: Gemini 0°–30° (Own sign) Virgo 15°–30° (own) / 0°–15° (MLT) | K7: Gemini, Virgo, Libra, Aquarius | L7: Aries, Leo, Sagittarius, Capricorn | M7: Direct: ±14.0° Rx: ±12.0° | N7: • Lord of Pisces (Jupiter) in Kendra from Lagna or Moon • Venus exalted in Pisces in Kendra • Mercury in Pisces with exalted planet in Kendra from Moon
A8: Jupiter | B8: Brihaspati | C8: Cancer | D8: 5° | E8: Cancer 0°–10° | F8: Capricorn | G8: 5° | H8: Capricorn 0°–10° | I8: Sagittarius 0°–10° | J8: Sagittarius 10°–30° (own) / 0°–10° (MLT) Pisces 0°–30° (Own sign) | K8: Aries, Cancer, Leo, Scorpio, Sagittarius, Pisces | L8: Taurus, Capricorn, Aquarius | M8: Direct: ±11.0° Rx: ±8.0° | N8: • Lord of Capricorn (Saturn) in Kendra from Lagna or Moon • Mars exalted in Capricorn in Kendra • Jupiter in Capricorn aspected by exalted planet
A9: Venus | B9: Shukra | C9: Pisces | D9: 27° | E9: Pisces 22°–29° | F9: Virgo | G9: 27° | H9: Virgo 22°–29° | I9: Libra 0°–15° | J9: Taurus 0°–30° (Own sign) Libra 15°–30° (own) / 0°–15° (MLT) | K9: Taurus, Gemini, Libra, Capricorn, Aquarius, Pisces | L9: Aries, Cancer, Scorpio, Sagittarius | M9: Direct: ±10.0° Rx: ±8.0° | N9: • Lord of Virgo (Mercury) in Kendra from Lagna or Moon • Mercury exalted in Virgo in Kendra • Venus in Virgo with exalted planet conjunct or in Kendra from Moon
A10: Saturn | B10: Shani | C10: Libra | D10: 20° | E10: Libra 15°–25° | F10: Aries | G10: 20° | H10: Aries 15°–25° | I10: Aquarius 0°–20° | J10: Capricorn 0°–30° (Own sign) Aquarius 20°–30° (own) / 0°–20° (MLT) | K10: Taurus, Gemini, Virgo, Libra, Capricorn, Aquarius | L10: Sagittarius, Pisces | M10: Direct: ±15.0° Rx: ±15.0° | N10: • Lord of Aries (Mars) in Kendra from Lagna or Moon • Sun exalted in Aries in Kendra • Saturn in Aries with Mars in Kendra from Lagna or Moon
A11: Rahu | B11: Rahu | C11: Taurus | D11: 20° | E11: Taurus 15°–25° | F11: Scorpio | G11: 20° | H11: Scorpio 15°–25° | I11: None (shadow node) | J11: Aquarius 0°–30° (Own sign — BPHS convention) Gemini 0°–30° (Co-lordship — Parashari view) | K11: Taurus, Gemini, Virgo, Libra, Capricorn, Aquarius | L11: Aries, Sagittarius, Pisces | M11: N/A (node) | N11: • Disputed: Rahu neecha bhanga less clearly defined in classical texts • Some texts: lord of Taurus (Venus) in Kendra cancels [Note] Rahu always retrograde (mean node). Always 180° from Ketu. Amplifies/intensifies the planet it conjoins. Own sign assignment contested — Aquarius (BPHS) most common.
A12: Ketu | B12: Ketu | C12: Scorpio | D12: 20° | E12: Scorpio 15°–25° | F12: Taurus | G12: 20° | H12: Taurus 15°–25° | I12: None (shadow node) | J12: Scorpio 0°–30° (Own sign — BPHS convention) Pisces 0°–30° (Co-lordship — Parashari view) | K12: Aries, Cancer, Scorpio, Pisces | L12: Leo, Sagittarius, Capricorn | M12: N/A (node) | N12: • Ketu neecha bhanga less defined; Mars in Kendra generally helps [Note] Ketu always retrograde (mean node). Always 180° from Rahu. Spiritualises / detaches the planet it conjoins. Own sign assignment contested — Scorpio (BPHS) most common.
A15: Dignity Scoring Weights — used by CALC_PlanetPositions to compute planet strength modifier
A16: Dignity level | B16: Sanskrit | C16: Weight (score modifier) | D16: Applies when...
A17: Deep exaltation | B17: Paramauchcha | C17: +2.0 | D17: Within ±5° of exact exaltation degree
A18: Exaltation | B18: Uchcha | C18: +1.5 | D18: In exaltation sign, outside deep exalt range
A19: Mooltrikona | B19: Mooltrikona | C19: +1.0 | D19: Within mooltrikona degree range
A20: Own sign | B20: Swarashi | C20: +0.75 | D20: In own sign, outside mooltrikona range
A21: Friendly sign | B21: Mitra Rashi | C21: +0.5 | D21: In sign ruled by a natural friend
A22: Neutral sign | B22: Sama Rashi | C22: 0.0 | D22: In sign ruled by a neutral planet
A23: Enemy sign | B23: Shatru Rashi | C23: -0.5 | D23: In sign ruled by a natural enemy
A24: Debilitation | B24: Neecha | C24: -1.5 | D24: In debilitation sign
A25: Deep debilitation | B25: Paramaneecha | C25: -2.0 | D25: Within ±5° of exact debilitation degree
A26: Combust (direct) | B26: Asta (direct) | C26: -1.0 | D26: Within Sun's combustion orb, direct motion
A27: Combust (Rx) | B27: Asta (Vakri) | C27: -0.5 | D27: Within Sun's combustion orb, retrograde (reduced effect)
... A29: Neecha Bhanga | B29: Neecha Bhanga | C29: +1.0 | D29: Debilitation cancelled — treat as neutral or better
A33: Dignity Matrix — Sign × Planet · CALC_PlanetPositions: INDEX(matrix, MATCH(planet, header_row), MATCH(sign, header_col))
A34: Sign | B34: Sun | C34: Moon | D34: Mars | E34: Mercury | F34: Jupiter | G34: Venus | H34: Saturn | I34: Rahu | J34: Ketu
A35: Aries | B35: Exaltation | C35: Neutral sign | D35: Mooltrikona | E35: Neutral sign | F35: Friendly sign | G35: Neutral sign | H35: Debilitation | I35: Neutral sign | J35: Friendly sign
A36: Taurus | B36: Enemy sign | C36: Exaltation | D36: Neutral sign | E36: Enemy sign | F36: Neutral sign | G36: Own sign | H36: Friendly sign | I36: Exaltation | J36: Debilitation
A37: Gemini | B37: Neutral sign | C37: Neutral sign | D37: Enemy sign | E37: Own sign | F37: Enemy sign | G37: Friendly sign | H37: Friendly sign | I37: Own sign | J37: Enemy sign
A38: Cancer | B38: Friendly sign | C38: Own sign | D38: Debilitation | E38: Enemy sign | F38: Exaltation | G38: Neutral sign | H38: Enemy sign | I38: Enemy sign | J38: Friendly sign
A39: Leo | B39: Mooltrikona | C39: Friendly sign | D39: Friendly sign | E39: Neutral sign | F39: Friendly sign | G39: Enemy sign | H39: Enemy sign | I39: Enemy sign | J39: Neutral sign
A40: Virgo | B40: Enemy sign | C40: Neutral sign | D40: Neutral sign | E40: Exaltation | F40: Enemy sign | G40: Debilitation | H40: Friendly sign | I40: Friendly sign | J40: Enemy sign
A41: Libra | B41: Debilitation | C41: Friendly sign | D41: Neutral sign | E41: Friendly sign | F41: Enemy sign | G41: Mooltrikona | H41: Exaltation | I41: Friendly sign | J41: Enemy sign
A42: Scorpio | B42: Enemy sign | C42: Debilitation | D42: Own sign | E42: Enemy sign | F42: Friendly sign | G42: Neutral sign | H42: Enemy sign | I42: Debilitation | J42: Exaltation
A43: Sagittarius | B43: Friendly sign | C43: Friendly sign | D43: Friendly sign | E43: Neutral sign | F43: Mooltrikona | G43: Neutral sign | H43: Neutral sign | I43: Neutral sign | J43: Neutral sign
